Workbook

Sheet التقرير العام
A1: نظام إدارة التصنيع للغير المالي واللوجستي - شركة RTX للبلاستيك
A4: م | B4: اسم العميل | C4: إجمالي الخامات المرسلة (كجم) | D4: إجمالي المنتجات المستلمة (كجم) | E4: رصيد الخامات المتبقي (كجم) | F4: إجمالي عمولة التصنيع (جنية) | G4: إجمالي الدفعات المسددة (جنية) | H4: الرصيد المالي المتبقي للمصنع (جنية)
A5: 1 | B5: محمد ممدوح (مشبك) | C5: ='العميل 1 (مشبك)'!A4 -> 8989 | D5: ='العميل 1 (مشبك)'!C4 -> 6687 | E5: ='العميل 1 (مشبك)'!D4 -> 2302 | F5: ='العميل 1 (مشبك)'!G4 -> 73557 | G5: ='العميل 1 (مشبك)'!H4 -> 66000 | H5: ='العميل 1 (مشبك)'!J4 -> 7557
A6: 2 | B6: محمد ممدوح (فاصل) | C6: ='العميل 2 (فاصل)'!A4 -> 418 | D6: ='العميل 2 (فاصل)'!C4 -> 418 | E6: ='العميل 2 (فاصل)'!D4 -> 0 | F6: ='العميل 2 (فاصل)'!F4 -> 7106 | G6: ='العميل 2 (فاصل)'!H4 -> 0 | H6: ='العميل 2 (فاصل)'!J4 -> 7106
A7: 3 | B7: العميل 3 | C7: 0 | D7: 0 | E7: 0 | F7: 0 | G7: 0 | H7: 0
A8: 4 | B8: العميل 4 | C8: 0 | D8: 0 | E8: 0 | F8: 0 | G8: 0 | H8: 0
A9: 5 | B9: العميل 5 | C9: 0 | D9: 0 | E9: 0 | F9: 0 | G9: 0 | H9: 0
A10: 6 | B10: العميل 6 | C10: 0 | D10: 0 | E10: 0 | F10: 0 | G10: 0 | H10: 0
A11: 7 | B11: العميل 7 | C11: 0 | D11: 0 | E11: 0 | F11: 0 | G11: 0 | H11: 0
A12: 8 | B12: العميل 8 | C12: 0 | D12: 0 | E12: 0 | F12: 0 | G12: 0 | H12: 0
A13: 9 | B13: العميل 9 | C13: 0 | D13: 0 | E13: 0 | F13: 0 | G13: 0 | H13: 0
A14: 10 | B14: العميل 10 | C14: 0 | D14: 0 | E14: 0 | F14: 0 | G14: 0 | H14: 0
B15: الإجماليات | C15: =SUM(C5:C14) -> 9407 | D15: =SUM(D5:D14) -> 7105 | E15: =SUM(E5:E14) -> 2302 | F15: =SUM(F5:F14) -> 80663 | G15: =SUM(G5:G14) -> 66000 | H15: =SUM(H5:H14) -> 14663

Sheet العميل 1 (مشبك)
A1: حساب كشف حركة: محمد ممدوح (منتج: مشبك - وزن 7 جرام - كيس 100 قطعة)
A3: إجمالي خامات مرسلة | C3: إجمالي منتج مستلم (كجم) | D3: متبقي خامات بالمصنع | E3: عدد الأكياس المستلمة | G3: إجمالي العمولات | H3: إجمالي المدفوعات | J3: رصيد مالي للمصنع | L3: ء
A4: =SUM(D8:D51) -> 8989 | C4: =SUM(H8:H51) -> 6687 | D4: =A4-C4 -> 2302 | E4: =SUM(G8:G51) -> 955285.71 | G4: =SUM(J8:J51) -> 73557 | H4: =SUM(K8:K51) -> 66000 | J4: =G4-H4 -> 7557
A7: رقم الإذن | B7: التاريخ | C7: البيان / تفاصيل الحركة | D7: تسليم خامات (كجم) | E7: نوع الصنف | F7: الوزن التلقائي (جرام) | G7: الكمية الفرعية (بالعدد) | H7: استلام منتج (كجم) | I7: سعر التصنيع / كجم | J7: عمولة مستحقة (جنية) | K7: دفعات مسددة (جنية) | L7: رصيد الخامات التراكمي | M7: الرصيد المالي التراكمي
A8: 1 | B8: 2026-06-19 | C8: سبيكال مخرز | D8: 3319 | E8: مشبك | F8: 7 | G8: =IF(H8<>"", (H8*1000)/F8, "") -> 259571.43 | H8: 1817 | I8: 11 | J8: =IF(H8<>"", H8*I8, 0) -> 19987 | L8: =D8-IF(H8<>"",H8,0) -> 1502 | M8: =J8-IF(K8<>"",K8,0) -> 19987
A9: 2 | B9: 2026-06-20 | C9: سبيكال مخرز | E9: مشبك | F9: 7 | G9: =IF(H9<>"", (H9*1000)/F9, "") -> 44857.143 | H9: 314 | I9: 11 | J9: =IF(H9<>"", H9*I9, 0) -> 3454 | L9: =L8+IF(D9<>"",D9,0)-IF(H9<>"",H9,0) -> 1188 | M9: =M8+J9-IF(K9<>"",K9,0) -> 23441
A10: 3 | B10: 2026-06-21 | C10: سبيكال مخرز | E10: مشبك | F10: 7 | G10: =IF(H10<>"", (H10*1000)/F10, "") -> 32142.857 | H10: 225 | I10: 11 | J10: =IF(H10<>"", H10*I10, 0) -> 2475 | L10: =L9+IF(D10<>"",D10,0)-IF(H10<>"",H10,0) -> 963 | M10: =M9+J10-IF(K10<>"",K10,0) -> 25916
A11: 4 | B11: 2026-06-22 | C11: سبيكال مخرز | D11: 2110 | E11: مشبك | F11: 7 | G11: =IF(H11<>"", (H11*1000)/F11, "") | I11: 11 | J11: =IF(H11<>"", H11*I11, 0) -> 0 | L11: =L10+IF(D11<>"",D11,0)-IF(H11<>"",H11,0) -> 3073 | M11: =M10+J11-IF(K11<>"",K11,0) -> 25916
A12: 5 | B12: 2026-06-22 | C12: سبيكال مخرز | E12: مشبك | F12: 7 | G12: =IF(H12<>"", (H12*1000)/F12, "") -> 30428.571 | H12: 213 | I12: 11 | J12: =IF(H12<>"", H12*I12, 0) -> 2343 | L12: =L11+IF(D12<>"",D12,0)-IF(H12<>"",H12,0) -> 2860 | M12: =M11+J12-IF(K12<>"",K12,0) -> 28259
A13: 6 | B13: 2026-06-23 | C13: سبيكال مخرز | E13: مشبك | F13: 7 | G13: =IF(H13<>"", (H13*1000)/F13, "") -> 37857.143 | H13: 265 | I13: 11 | J13: =IF(H13<>"", H13*I13, 0) -> 2915 | L13: =L12+IF(D13<>"",D13,0)-IF(H13<>"",H13,0) -> 2595 | M13: =M12+J13-IF(K13<>"",K13,0) -> 31174
A14: 7 | B14: 2026-06-24 | C14: سبيكال مخرز | E14: مشبك | F14: 7 | G14: =IF(H14<>"", (H14*1000)/F14, "") -> 9285.7143 | H14: 65 | I14: 11 | J14: =IF(H14<>"", H14*I14, 0) -> 715 | L14: =L13+IF(D14<>"",D14,0)-IF(H14<>"",H14,0) -> 2530 | M14: =M13+J14-IF(K14<>"",K14,0) -> 31889
A15: 8 | B15: 46200 | C15: سبيكال مخرز | E15: مشبك | F15: 7 | G15: =IF(H15<>"", (H15*1000)/F15, "") -> 56285.714 | H15: 394 | I15: 11 | J15: =IF(H15<>"", H15*I15, 0) -> 4334 | L15: =L14+IF(D15<>"",D15,0)-IF(H15<>"",H15,0) -> 2136 | M15: =M14+J15-IF(K15<>"",K15,0) -> 36223
A16: 9 | B16: 46202 | C16: سبيكال مخرز | E16: مشبك | F16: 7 | G16: =IF(H16<>"", (H16*1000)/F16, "") -> 22142.857 | H16: 155 | I16: 11 | J16: =IF(H16<>"", H16*I16, 0) -> 1705 | L16: =L15+IF(D16<>"",D16,0)-IF(H16<>"",H16,0) -> 1981 | M16: =M15+J16-IF(K16<>"",K16,0) -> 37928
A17: 10 | B17: 46203 | C17: سبيكال مخرز | E17: مشبك | F17: 7 | G17: =IF(H17<>"", (H17*1000)/F17, "") -> 43857.143 | H17: 307 | I17: 11 | J17: =IF(H17<>"", H17*I17, 0) -> 3377 | L17: =L16+IF(D17<>"",D17,0)-IF(H17<>"",H17,0) -> 1674 | M17: =M16+J17-IF(K17<>"",K17,0) -> 41305
A18: 11 | B18: 46204 | C18: سبيكال مخرز | D18: 2075 | G18: =IF(H18<>"", (H18*1000)/F18, "") | J18: =IF(H18<>"", H18*I18, 0) -> 0 | L18: =L17+IF(D18<>"",D18,0)-IF(H18<>"",H18,0) -> 3749 | M18: =M17+J18-IF(K18<>"",K18,0) -> 41305
A19: 11 | B19: 46203 | C19: دفعه نقدي | G19: =IF(H19<>"", (H19*1000)/F19, "") | J19: =IF(H19<>"", H19*I19, 0) -> 0 | K19: 20000 | L19: =L18+IF(D19<>"",D19,0)-IF(H19<>"",H19,0) -> 3749 | M19: =M18+J19-IF(K19<>"",K19,0) -> 21305
A20: 12 | B20: 46204 | C20: دفعه نقدي | G20: =IF(H20<>"", (H20*1000)/F20, "") | J20: =IF(H20<>"", H20*I20, 0) -> 0 | K20: 15000 | L20: =L19+IF(D20<>"",D20,0)-IF(H20<>"",H20,0) -> 3749 | M20: =M19+J20-IF(K20<>"",K20,0) -> 6305
A21: 13 | B21: 46204 | C21: سبيكال مخرز | E21: مشبك | F21: 7 | G21: =IF(H21<>"", (H21*1000)/F21, "") -> 26428.571 | H21: 185 | I21: 11 | J21: =IF(H21<>"", H21*I21, 0) -> 2035 | L21: =L20+IF(D21<>"",D21,0)-IF(H21<>"",H21,0) -> 3564 | M21: =M20+J21-IF(K21<>"",K21,0) -> 8340
A22: 14 | B22: 46210 | C22: سبيكال مخرز | E22: مشبك | F22: 7 | G22: =IF(H22<>"", (H22*1000)/F22, "") -> 19857.143 | H22: 139 | I22: 11 | J22: =IF(H22<>"", H22*I22, 0) -> 1529 | L22: =L21+IF(D22<>"",D22,0)-IF(H22<>"",H22,0) -> 3425 | M22: =M21+J22-IF(K22<>"",K22,0) -> 9869
A23: 15 | B23: 46210 | C23: سبيكال مخرز | E23: مشبك | F23: 7 | G23: =IF(H23<>"", (H23*1000)/F23, "") -> 32714.286 | H23: 229 | I23: 11 | J23: =IF(H23<>"", H23*I23, 0) -> 2519 | L23: =L22+IF(D23<>"",D23,0)-IF(H23<>"",H23,0) -> 3196 | M23: =M22+J23-IF(K23<>"",K23,0) -> 12388
A24: 16 | B24: 46210 | C24: سبيكال مخرز | E24: مشبك | F24: 7 | G24: =IF(H24<>"", (H24*1000)/F24, "") -> 34857.143 | H24: 244 | I24: 11 | J24: =IF(H24<>"", H24*I24, 0) -> 2684 | L24: =L23+IF(D24<>"",D24,0)-IF(H24<>"",H24,0) -> 2952 | M24: =M23+J24-IF(K24<>"",K24,0) -> 15072
A25: 17 | B25: 46210 | C25: سبيكال مخرز | E25: مشبك | F25: 7 | G25: =IF(H25<>"", (H25*1000)/F25, "") -> 51428.571 | H25: 360 | I25: 11 | J25: =IF(H25<>"", H25*I25, 0) -> 3960 | L25: =L24+IF(D25<>"",D25,0)-IF(H25<>"",H25,0) -> 2592 | M25: =M24+J25-IF(K25<>"",K25,0) -> 19032
A26: 18 | B26: 46210 | C26: سبيكال مخرز | E26: مشبك | F26: 7 | G26: =IF(H26<>"", (H26*1000)/F26, "") -> 50142.857 | H26: 351 | I26: 11 | J26: =IF(H26<>"", H26*I26, 0) -> 3861 | L26: =L25+IF(D26<>"",D26,0)-IF(H26<>"",H26,0) -> 2241 | M26: =M25+J26-IF(K26<>"",K26,0) -> 22893
A27: 19 | B27: 46210 | C27: سبيكال مخرز | E27: مشبك | F27: 7 | G27: =IF(H27<>"", (H27*1000)/F27, "") -> 66571.429 | H27: 466 | I27: 11 | J27: =IF(H27<>"", H27*I27, 0) -> 5126 | L27: =L26+IF(D27<>"",D27,0)-IF(H27<>"",H27,0) -> 1775 | M27: =M26+J27-IF(K27<>"",K27,0) -> 28019
A28: 20 | B28: 46210 | C28: دفعه نقدي | J28: =IF(H28<>"", H28*I28, 0) -> 0 | K28: 20000 | L28: =L27+IF(D28<>"",D28,0)-IF(H28<>"",H28,0) -> 1775 | M28: =M27+J28-IF(K28<>"",K28,0) -> 8019
A29: 21 | B29: 46211 | C29: سبيكال مخرز | E29: مشبك | F29: 7 | G29: =IF(H29<>"", (H29*1000)/F29, "") -> 17000 | H29: 119 | I29: 11 | J29: =IF(H29<>"", H29*I29, 0) -> 1309 | L29: =L28+IF(D29<>"",D29,0)-IF(H29<>"",H29,0) -> 1656 | M29: =M28+J29-IF(K29<>"",K29,0) -> 9328
A30: 22 | B30: 46211 | C30: سبيكال مخرز | E30: مشبك | F30: 7 | G30: =IF(H30<>"", (H30*1000)/F30, "") -> 9142.8571 | H30: 64 | I30: 11 | J30: =IF(H30<>"", H30*I30, 0) -> 704 | L30: =L29+IF(D30<>"",D30,0)-IF(H30<>"",H30,0) -> 1592 | M30: =M29+J30-IF(K30<>"",K30,0) -> 10032
A31: 23 | B31: 46214 | C31: دفعه نقدي | G31: =IF(H31<>"", (H31*1000)/F31, "") | J31: =IF(H31<>"", H31*I31, 0) -> 0 | K31: 11000 | L31: =L30+IF(D31<>"",D31,0)-IF(H31<>"",H31,0) -> 1592 | M31: =M30+J31-IF(K31<>"",K31,0) -> -968
A32: 24 | B32: 46217 | C32: ريسايكل | D32: 1485 | E32: مشبك | F32: 7 | G32: =IF(H32<>"", (H32*1000)/F32, "") | J32: =IF(H32<>"", H32*I32, 0) -> 0 | L32: =L31+IF(D32<>"",D32,0)-IF(H32<>"",H32,0) -> 3077 | M32: =M31+J32-IF(K32<>"",K32,0) -> -968
A33: 25 | B33: 46218 | C33: سبيكال مخرز | E33: مشبك | F33: 7 | G33: =IF(H33<>"", (H33*1000)/F33, "") -> 72285.714 | H33: 506 | I33: 11 | J33: =IF(H33<>"", H33*I33, 0) -> 5566 | L33: =L32+IF(D33<>"",D33,0)-IF(H33<>"",H33,0) -> 2571 | M33: =M32+J33-IF(K33<>"",K33,0) -> 4598
A34: 26 | B34: 46218 | C34: سبيكال مخرز | E34: مشبك | F34: 7 | G34: =IF(H34<>"", (H34*1000)/F34, "") -> 38428.571 | H34: 269 | I34: 11 | J34: =IF(H34<>"", H34*I34, 0) -> 2959 | L34: =L33+IF(D34<>"",D34,0)-IF(H34<>"",H34,0) -> 2302 | M34: =M33+J34-IF(K34<>"",K34,0) -> 7557
C35: سبيكال مخرز | E35: مشبك | F35: 7 | G35: =IF(H35<>"", (H35*1000)/F35, "") | I35: 11 | J35: =IF(H35<>"", H35*I35, 0) -> 0 | L35: =L34+IF(D35<>"",D35,0)-IF(H35<>"",H35,0) -> 2302 | M35: =M34+J35-IF(K35<>"",K35,0) -> 7557
C36: سبيكال مخرز | E36: مشبك | F36: 7 | G36: =IF(H36<>"", (H36*1000)/F36, "") | I36: 11 | J36: =IF(H36<>"", H36*I36, 0) -> 0 | L36: =L35+IF(D36<>"",D36,0)-IF(H36<>"",H36,0) -> 2302 | M36: =M35+J36-IF(K36<>"",K36,0) -> 7557
C37: سبيكال مخرز | E37: مشبك | F37: 7 | G37: =IF(H37<>"", (H37*1000)/F37, "") | I37: 11 | J37: =IF(H37<>"", H37*I37, 0) -> 0 | L37: =L36+IF(D37<>"",D37,0)-IF(H37<>"",H37,0) -> 2302 | M37: =M36+J37-IF(K37<>"",K37,0) -> 7557
C38: سبيكال مخرز | E38: مشبك | F38: 7 | G38: =IF(H38<>"", (H38*1000)/F38, "") | I38: 11 | J38: =IF(H38<>"", H38*I38, 0) -> 0 | L38: =L37+IF(D38<>"",D38,0)-IF(H38<>"",H38,0) -> 2302 | M38: =M37+J38-IF(K38<>"",K38,0) -> 7557
C39: سبيكال مخرز | E39: مشبك | F39: 7 | G39: =IF(H39<>"", (H39*1000)/F39, "") | I39: 11 | J39: =IF(H39<>"", H39*I39, 0) -> 0 | L39: =L38+IF(D39<>"",D39,0)-IF(H39<>"",H39,0) -> 2302 | M39: =M38+J39-IF(K39<>"",K39,0) -> 7557
C40: سبيكال مخرز | E40: مشبك | F40: 7 | G40: =IF(H40<>"", (H40*1000)/F40, "") | I40: 11 | J40: =IF(H40<>"", H40*I40, 0) -> 0 | L40: =L39+IF(D40<>"",D40,0)-IF(H40<>"",H40,0) -> 2302 | M40: =M39+J40-IF(K40<>"",K40,0) -> 7557
C41: سبيكال مخرز | E41: مشبك | F41: 7 | G41: =IF(H41<>"", (H41*1000)/F41, "") | I41: 11 | J41: =IF(H41<>"", H41*I41, 0) -> 0 | L41: =L40+IF(D41<>"",D41,0)-IF(H41<>"",H41,0) -> 2302 | M41: =M40+J41-IF(K41<>"",K41,0) -> 7557
C42: سبيكال مخرز | E42: مشبك | F42: 7 | G42: =IF(H42<>"", (H42*1000)/F42, "") | I42: 11 | J42: =IF(H42<>"", H42*I42, 0) -> 0 | L42: =L41+IF(D42<>"",D42,0)-IF(H42<>"",H42,0) -> 2302 | M42: =M41+J42-IF(K42<>"",K42,0) -> 7557
C43: سبيكال مخرز | E43: مشبك | F43: 7 | G43: =IF(H43<>"", (H43*1000)/F43, "") | I43: 11 | J43: =IF(H43<>"", H43*I43, 0) -> 0 | L43: =L42+IF(D43<>"",D43,0)-IF(H43<>"",H43,0) -> 2302 | M43: =M42+J43-IF(K43<>"",K43,0) -> 7557
...

Sheet العميل 2 (فاصل)
A1: حساب كشف حركة: محمد ممدوح (منتج: فاصل - وزن 3 جرام)
A3: إجمالي خامات مرسلة | C3: إجمالي منتج مستلم (كجم) | D3: متبقي خامات بالمصنع | F3: إجمالي العمولات | H3: إجمالي المدفوعات | J3: رصيد مالي للمصنع
A4: =SUM(D8:D30) -> 418 | C4: =SUM(H8:H30) -> 418 | D4: =A4-C4 -> 0 | F4: =SUM(J8:J30) -> 7106 | H4: =SUM(K8:K30) -> 0 | J4: =F4-H4 -> 7106
A7: رقم الإذن | B7: التاريخ | C7: البيان / تفاصيل الحركة | D7: تسليم خامات (كجم) | E7: نوع الصنف | F7: الوزن التلقائي (جرام) | G7: الكمية الفرعية (بالعدد) | H7: استلام منتج (كجم) | I7: سعر التصنيع / كجم | J7: عمولة مستحقة (جنية) | K7: دفعات مسددة (جنية) | L7: رصيد الخامات التراكمي | M7: الرصيد المالي التراكمي
A8: 1 | B8: 2026-06-24 | C8: بيور 60-80 | D8: 250 | E8: فاصل | F8: 3 | G8: =IF(H8<>"", (H8*1000)/F8, "") | I8: 17 | J8: =IF(H8<>"", H8*I8, 0) -> 0 | L8: =D8-IF(H8<>"",H8,0) -> 250 | M8: =J8-IF(K8<>"",K8,0) -> 0
A9: 2 | B9: 2026-06-24 | C9: فاصل 1 مللي | E9: فاصل | F9: 3 | G9: =IF(H9<>"", (H9*1000)/F9, "") -> 17333.333 | H9: 52 | I9: 17 | J9: =IF(H9<>"", H9*I9, 0) -> 884 | L9: =L8+IF(D9<>"",D9,0)-IF(H9<>"",H9,0) -> 198 | M9: =M8+J9-IF(K9<>"",K9,0) -> 884
A10: 3 | B10: 2026-06-27 | C10: فاصل 1 مللي | E10: فاصل | F10: 3 | G10: =IF(H10<>"", (H10*1000)/F10, "") -> 31000 | H10: 93 | I10: 17 | J10: =IF(H10<>"", H10*I10, 0) -> 1581 | L10: =L9+IF(D10<>"",D10,0)-IF(H10<>"",H10,0) -> 105 | M10: =M9+J10-IF(K10<>"",K10,0) -> 2465
A11: 4 | B11: 46210 | C11: فاصل 1 مللي | E11: فاصل | F11: 3 | G11: =IF(H11<>"", (H11*1000)/F11, "") -> 15666.667 | H11: 47 | I11: 17 | J11: =IF(H11<>"", H11*I11, 0) -> 799 | L11: =L10+IF(D11<>"",D11,0)-IF(H11<>"",H11,0) -> 58 | M11: =M10+J11-IF(K11<>"",K11,0) -> 3264
A12: 5 | B12: 46210 | C12: فاصل 1 مللي | E12: فاصل | F12: 3 | G12: =IF(H12<>"", (H12*1000)/F12, "") -> 29333.333 | H12: 88 | I12: 17 | J12: =IF(H12<>"", H12*I12, 0) -> 1496 | L12: =L11+IF(D12<>"",D12,0)-IF(H12<>"",H12,0) -> -30 | M12: =M11+J12-IF(K12<>"",K12,0) -> 4760
A13: 6 | B13: 46210 | C13: فاصل 1 مللي | E13: فاصل | F13: 3 | G13: =IF(H13<>"", (H13*1000)/F13, "") -> 46000 | H13: 138 | I13: 17 | J13: =IF(H13<>"", H13*I13, 0) -> 2346 | L13: =L12+IF(D13<>"",D13,0)-IF(H13<>"",H13,0) -> -168 | M13: =M12+J13-IF(K13<>"",K13,0) -> 7106
A14: 7 | B14: 46211 | C14: بيور 60-80 | D14: 150 | E14: فاصل | F14: 3 | G14: =IF(H14<>"", (H14*1000)/F14, "") | I14: 17 | J14: =IF(H14<>"", H14*I14, 0) -> 0 | L14: =L13+IF(D14<>"",D14,0)-IF(H14<>"",H14,0) -> -18 | M14: =M13+J14-IF(K14<>"",K14,0) -> 7106
A15: 8 | B15: بواقي | C15: بيور 60-80 | D15: 18 | E15: فاصل | F15: 3 | G15: =IF(H15<>"", (H15*1000)/F15, "") | I15: 17 | J15: =IF(H15<>"", H15*I15, 0) -> 0 | L15: =L14+IF(D15<>"",D15,0)-IF(H15<>"",H15,0) -> 0 | M15: =M14+J15-IF(K15<>"",K15,0) -> 7106
E16: فاصل | F16: 3 | G16: =IF(H16<>"", (H16*1000)/F16, "") | I16: 17 | J16: =IF(H16<>"", H16*I16, 0) -> 0 | L16: =L15+IF(D16<>"",D16,0)-IF(H16<>"",H16,0) -> 0 | M16: =M15+J16-IF(K16<>"",K16,0) -> 7106
E17: فاصل | F17: 3 | G17: =IF(H17<>"", (H17*1000)/F17, "") | I17: 17 | J17: =IF(H17<>"", H17*I17, 0) -> 0 | L17: =L16+IF(D17<>"",D17,0)-IF(H17<>"",H17,0) -> 0 | M17: =M16+J17-IF(K17<>"",K17,0) -> 7106
E18: فاصل | F18: 3 | G18: =IF(H18<>"", (H18*1000)/F18, "") | I18: 17 | J18: =IF(H18<>"", H18*I18, 0) -> 0 | L18: =L17+IF(D18<>"",D18,0)-IF(H18<>"",H18,0) -> 0 | M18: =M17+J18-IF(K18<>"",K18,0) -> 7106
E19: فاصل | F19: 3 | G19: =IF(H19<>"", (H19*1000)/F19, "") | I19: 17 | J19: =IF(H19<>"", H19*I19, 0) -> 0 | L19: =L18+IF(D19<>"",D19,0)-IF(H19<>"",H19,0) -> 0 | M19: =M18+J19-IF(K19<>"",K19,0) -> 7106
E20: فاصل | F20: 3 | G20: =IF(H20<>"", (H20*1000)/F20, "") | I20: 17 | J20: =IF(H20<>"", H20*I20, 0) -> 0 | L20: =L19+IF(D20<>"",D20,0)-IF(H20<>"",H20,0) -> 0 | M20: =M19+J20-IF(K20<>"",K20,0) -> 7106
E21: فاصل | F21: 3 | G21: =IF(H21<>"", (H21*1000)/F21, "") | I21: 17 | J21: =IF(H21<>"", H21*I21, 0) -> 0 | L21: =L20+IF(D21<>"",D21,0)-IF(H21<>"",H21,0) -> 0 | M21: =M20+J21-IF(K21<>"",K21,0) -> 7106
E22: فاصل | F22: 3 | G22: =IF(H22<>"", (H22*1000)/F22, "") | I22: 17 | J22: =IF(H22<>"", H22*I22, 0) -> 0 | L22: =L21+IF(D22<>"",D22,0)-IF(H22<>"",H22,0) -> 0 | M22: =M21+J22-IF(K22<>"",K22,0) -> 7106
E23: فاصل | F23: 3 | G23: =IF(H23<>"", (H23*1000)/F23, "") | I23: 17 | J23: =IF(H23<>"", H23*I23, 0) -> 0 | L23: =L22+IF(D23<>"",D23,0)-IF(H23<>"",H23,0) -> 0 | M23: =M22+J23-IF(K23<>"",K23,0) -> 7106
E24: فاصل | F24: 3 | G24: =IF(H24<>"", (H24*1000)/F24, "") | I24: 17 | J24: =IF(H24<>"", H24*I24, 0) -> 0 | L24: =L23+IF(D24<>"",D24,0)-IF(H24<>"",H24,0) -> 0 | M24: =M23+J24-IF(K24<>"",K24,0) -> 7106
